Workbook

Sheet 说明
A2: 视频模型成本与售价利润表
A6: · 生成时间：2026-09-29 · 数据口径：单条视频、输出 1 个；音频（有声/静音）在所有渠道成本相同，不单独区分。
A8: · 覆盖渠道：Ark 官方（Seedance 2.5 / 2.0 / 2.0 Mini）、MiniMax 官方（H3 / H3-Max）、GASIC 中转（Seedance 按条）、阿里百炼（Wan3.0 北京 + 国际）。
A10: · 成本公式：Seedance 系 = ROUNDUP(时长×宽×高×24/1024) tokens ÷ 1e6 × 元/百万tokens；MiniMax = 输出秒 × 元/秒；GASIC = 2 元/条；百炼 Wan3.0 =（输出秒 + 输入视频秒）× 元/秒。
A12: · Wan3.0 编辑/延长/参考模式的输入视频按秒计费，表中“输入视频秒”列按典型值 5 秒估算（可在明细表 F 列按实际输入时长修改）。
A14: · 现行售价 = 平台现行报价（预扣最高成本候选，向上取整到 1 积分）→ 当前基本零加价，仅作对照。
A16: · 建议售价 = 成本 ÷ (1 − 毛利率)，毛利率按单条成本对数插值：最便宜行 80% → 最货行 40%，夹在 30%~95%；低参数行落在 50%~100%，高参数行落在 30%~50%。
A18: · 想调价：改『费率与参数』里的黄色费率/参数，或直接改『建议售价清单』H 列（目标毛利率）——全表与曲线自动重算（请用 Excel / WPS 打开）。
A20: · 费率来源：Seedance 2.5/2.0 = 官方文档价（已实测校准）；Mini = 2.0 牌价×官方 4 折活动（暂定）；MiniMax = 官方秒单价；GASIC = 2 元/条；百炼 Wan3.0 = 官方牌价（北京限时 7 折实付更低，已备注）。
A22: · 官方价格页：ark.volcengine.com/region:cn-beijing/docs/ark/model-pricing（Seedance）、docs.bailian.console.aliyun.com/zh/model-studio/model-pricing（万相3.0）。

Sheet 费率与参数
A1: ① 通用参数（黄色单元格可改，全表自动重算）
A2: 积分单价（元/积分） | B2: 0.01 | C2: 平台现状：1积分 = 0.01元
A3: 积分取整步长（积分） | B3: 1 | C3: 报价向上取整到该步长
A4: 最低积分 | B4: 1 | C4: 单任务最低预扣/售价
A5: 毛利率上限（低参数端） | B5: 0.5 | C5: 落在 50%~100% 区间
A6: 毛利率下限（高参数端） | B6: 0.15 | C6: 落在 30%~50% 区间
A8: ② Seedance 像素预设（token 计费公式用：tokens = ROUNDUP(时长×宽×高×帧率/1024)）
A9: 分辨率 | B9: 宽 | C9: 高 | D9: 帧率
A10: 480p | B10: 854 | C10: 480 | D10: 24
A11: 720p | B11: 1280 | C11: 720 | D11: 24
A12: 1080p | B12: 1920 | C12: 1080 | D12: 24
A14: ③ 成本费率表（黄色费率可改；改后两张明细表与曲线自动重算）
A15: 费率键（路由|渠道|分辨率） | B15: 路由 | C15: 渠道 | D15: 分辨率 | E15: 计费模式 | F15: 费率 | G15: 单位 | H15: 备注
A16: seedance-2.5|Ark官方|480p | B16: Seedance 2.5 | C16: Ark官方 | D16: 480p | E16: token | F16: 60 | G16: 元/百万tokens | H16: 官方文档价
A17: seedance-2.5|Ark官方|720p | B17: Seedance 2.5 | C17: Ark官方 | D17: 720p | E17: token | F17: 90 | G17: 元/百万tokens | H17: 官方文档价
A18: seedance-2.5|Ark官方|1080p | B18: Seedance 2.5 | C18: Ark官方 | D18: 1080p | E18: token | F18: 150 | G18: 元/百万tokens | H18: 官方文档价
A19: seedance-2.0|Ark官方|480p | B19: Seedance 2.0 | C19: Ark官方 | D19: 480p | E19: token | F19: 30 | G19: 元/百万tokens | H19: 官方文档价
A20: seedance-2.0|Ark官方|720p | B20: Seedance 2.0 | C20: Ark官方 | D20: 720p | E20: token | F20: 45 | G20: 元/百万tokens | H20: 官方文档价
A21: seedance-2.0|Ark官方|1080p | B21: Seedance 2.0 | C21: Ark官方 | D21: 1080p | E21: token | F21: 75 | G21: 元/百万tokens | H21: 官方文档价
A22: seedance-2.0-mini|Ark官方|480p | B22: Seedance 2.0 Mini（极速版） | C22: Ark官方 | D22: 480p | E22: token | F22: 12 | G22: 元/百万tokens | H22: 暂定：2.0牌价×官方4折活动，待核对
A23: seedance-2.0-mini|Ark官方|720p | B23: Seedance 2.0 Mini（极速版） | C23: Ark官方 | D23: 720p | E23: token | F23: 18 | G23: 元/百万tokens | H23: 暂定：同上
A24: seedance-2.0-mini|Ark官方|1080p | B24: Seedance 2.0 Mini（极速版） | C24: Ark官方 | D24: 1080p | E24: token | F24: 30 | G24: 元/百万tokens | H24: 暂定：同上
A25: minimax-h3|MiniMax官方|768p | B25: MiniMax H3（海螺） | C25: MiniMax官方 | D25: 768p | E25: per_second | F25: 0.5 | G25: 元/秒 | H25: 官方 0.50元/秒
A26: minimax-h3|MiniMax官方|2k | B26: MiniMax H3（海螺） | C26: MiniMax官方 | D26: 2k | E26: per_second | F26: 0.8 | G26: 元/秒 | H26: 官方 0.80元/秒
A27: minimax-h3-max|MiniMax官方|480p | B27: MiniMax H3-Max（海螺） | C27: MiniMax官方 | D27: 480p | E27: per_second | F27: 0.5 | G27: 元/秒 | H27: 官方未公布，暂按 0.50元/秒
... A36: wan3.0-video|百炼（国际）|1080p | B36: 万相3.0（Wan3.0） | C36: 百炼（国际） | D36: 1080p | E36: per_second | F36: 1.49884 | G36: 元/秒 | H36: 国际站牌价
A38: 计费模式：token = 按生成 tokens（Seedance 系）；per_second = 按秒（MiniMax、百炼 Wan3.0）；per_task = 按条（GASIC）。
A39: 百炼 Wan3.0 计费时长 = 输入视频时长 + 输出视频时长（编辑/延长/参考模式），失败不计费；北京地域 30 秒免费额度未计入。音频（有声/静音）各渠道成本相同，不单独区分。

Sheet 成本与现售价
A1: 成本与现行售价明细（现行售价 = 预扣最高成本候选 → 平台当前基本零加价，用于对照）
A3: 路由 | B3: 渠道 | C3: 模型 | D3: 分辨率 | E3: 时长(秒) | F3: 输入视频秒 | G3: 计费模式 | H3: tokens | I3: 成本(元) | J3: 现售价(积分) | K3: 现售价(元) | L3: 现行毛利率
A4: Seedance 2.5 | B4: Ark官方 | C4: doubao-seedance-2-5-260628 | D4: 480p | E4: 5 | F4: — | G4: token | H4: =ROUNDUP(E4*VLOOKUP(D4,费率与参数!$A$10:$D$12,2,0)*VLOOKUP(D4,费率与参数!$A$10:$D$12,3,0)*VLOOKUP(D4,费率与参数!$A$10:$D$12,4,0)/1024,0) -> 48038 | I4: =H4*VLOOKUP("seedance-2.5|Ark官方|480p",费率与参数!$A$16:$G$36,6,0)/1000000 -> 2.88228 | J4: =MAX(费率与参数!$B$4,CEILING(I4/费率与参数!$B$2,费率与参数!$B$3)) -> 289 | K4: =J4*费率与参数!$B$2 -> 2.89 | L4: =IF(K4>0,1-I4/K4,0) -> 0.0026712803
A5: Seedance 2.5 | B5: Ark官方 | C5: doubao-seedance-2-5-260628 | D5: 480p | E5: 10 | F5: — | G5: token | H5: =ROUNDUP(E5*VLOOKUP(D5,费率与参数!$A$10:$D$12,2,0)*VLOOKUP(D5,费率与参数!$A$10:$D$12,3,0)*VLOOKUP(D5,费率与参数!$A$10:$D$12,4,0)/1024,0) -> 96075 | I5: =H5*VLOOKUP("seedance-2.5|Ark官方|480p",费率与参数!$A$16:$G$36,6,0)/1000000 -> 5.7645 | J5: =MAX(费率与参数!$B$4,CEILING(I5/费率与参数!$B$2,费率与参数!$B$3)) -> 577 | K5: =J5*费率与参数!$B$2 -> 5.77 | L5: =IF(K5>0,1-I5/K5,0) -> 0.00095320624
A6: Seedance 2.5 | B6: Ark官方 | C6: doubao-seedance-2-5-260628 | D6: 720p | E6: 5 | F6: — | G6: token | H6: =ROUNDUP(E6*VLOOKUP(D6,费率与参数!$A$10:$D$12,2,0)*VLOOKUP(D6,费率与参数!$A$10:$D$12,3,0)*VLOOKUP(D6,费率与参数!$A$10:$D$12,4,0)/1024,0) -> 108000 | I6: =H6*VLOOKUP("seedance-2.5|Ark官方|720p",费率与参数!$A$16:$G$36,6,0)/1000000 -> 9.72 | J6: =MAX(费率与参数!$B$4,CEILING(I6/费率与参数!$B$2,费率与参数!$B$3)) -> 972 | K6: =J6*费率与参数!$B$2 -> 9.72 | L6: =IF(K6>0,1-I6/K6,0) -> 0
A7: Seedance 2.5 | B7: Ark官方 | C7: doubao-seedance-2-5-260628 | D7: 720p | E7: 10 | F7: — | G7: token | H7: =ROUNDUP(E7*VLOOKUP(D7,费率与参数!$A$10:$D$12,2,0)*VLOOKUP(D7,费率与参数!$A$10:$D$12,3,0)*VLOOKUP(D7,费率与参数!$A$10:$D$12,4,0)/1024,0) -> 216000 | I7: =H7*VLOOKUP("seedance-2.5|Ark官方|720p",费率与参数!$A$16:$G$36,6,0)/1000000 -> 19.44 | J7: =MAX(费率与参数!$B$4,CEILING(I7/费率与参数!$B$2,费率与参数!$B$3)) -> 1944 | K7: =J7*费率与参数!$B$2 -> 19.44 | L7: =IF(K7>0,1-I7/K7,0) -> 0
A8: Seedance 2.5 | B8: Ark官方 | C8: doubao-seedance-2-5-260628 | D8: 1080p | E8: 5 | F8: — | G8: token | H8: =ROUNDUP(E8*VLOOKUP(D8,费率与参数!$A$10:$D$12,2,0)*VLOOKUP(D8,费率与参数!$A$10:$D$12,3,0)*VLOOKUP(D8,费率与参数!$A$10:$D$12,4,0)/1024,0) -> 243000 | I8: =H8*VLOOKUP("seedance-2.5|Ark官方|1080p",费率与参数!$A$16:$G$36,6,0)/1000000 -> 36.45 | J8: =MAX(费率与参数!$B$4,CEILING(I8/费率与参数!$B$2,费率与参数!$B$3)) -> 3645 | K8: =J8*费率与参数!$B$2 -> 36.45 | L8: =IF(K8>0,1-I8/K8,0) -> 0
A9: Seedance 2.5 | B9: Ark官方 | C9: doubao-seedance-2-5-260628 | D9: 1080p | E9: 10 | F9: — | G9: token | H9: =ROUNDUP(E9*VLOOKUP(D9,费率与参数!$A$10:$D$12,2,0)*VLOOKUP(D9,费率与参数!$A$10:$D$12,3,0)*VLOOKUP(D9,费率与参数!$A$10:$D$12,4,0)/1024,0) -> 486000 | I9: =H9*VLOOKUP("seedance-2.5|Ark官方|1080p",费率与参数!$A$16:$G$36,6,0)/1000000 -> 72.9 | J9: =MAX(费率与参数!$B$4,CEILING(I9/费率与参数!$B$2,费率与参数!$B$3)) -> 7290 | K9: =J9*费率与参数!$B$2 -> 72.9 | L9: =IF(K9>0,1-I9/K9,0) -> 0
A10: Seedance 2.5 | B10: GASIC中转 | C10: doubao-seedance-2-5-260628 | D10: 480p | E10: 任意 | F10: — | G10: 按条 | H10: — | I10: =VLOOKUP("seedance-2.5|GASIC中转|任意",费率与参数!$A$16:$G$36,6,0) -> 2 | J10: =MAX(费率与参数!$B$4,CEILING(I10/费率与参数!$B$2,费率与参数!$B$3)) -> 200 | K10: =J10*费率与参数!$B$2 -> 2 | L10: =IF(K10>0,1-I10/K10,0) -> 0
A11: Seedance 2.5 | B11: GASIC中转 | C11: doubao-seedance-2-5-260628 | D11: 480p | E11: 任意 | F11: — | G11: 按条 | H11: — | I11: =VLOOKUP("seedance-2.5|GASIC中转|任意",费率与参数!$A$16:$G$36,6,0) -> 2 | J11: =MAX(费率与参数!$B$4,CEILING(I11/费率与参数!$B$2,费率与参数!$B$3)) -> 200 | K11: =J11*费率与参数!$B$2 -> 2 | L11: =IF(K11>0,1-I11/K11,0) -> 0
A12: Seedance 2.5 | B12: GASIC中转 | C12: doubao-seedance-2-5-260628 | D12: 480p | E12: 任意 | F12: — | G12: 按条 | H12: — | I12: =VLOOKUP("seedance-2.5|GASIC中转|任意",费率与参数!$A$16:$G$36,6,0) -> 2 | J12: =MAX(费率与参数!$B$4,CEILING(I12/费率与参数!$B$2,费率与参数!$B$3)) -> 200 | K12: =J12*费率与参数!$B$2 -> 2 | L12: =IF(K12>0,1-I12/K12,0) -> 0
A13: Seedance 2.5 | B13: GASIC中转 | C13: doubao-seedance-2-5-260628 | D13: 720p | E13: 任意 | F13: — | G13: 按条 | H13: — | I13: =VLOOKUP("seedance-2.5|GASIC中转|任意",费率与参数!$A$16:$G$36,6,0) -> 2 | J13: =MAX(费率与参数!$B$4,CEILING(I13/费率与参数!$B$2,费率与参数!$B$3)) -> 200 | K13: =J13*费率与参数!$B$2 -> 2 | L13: =IF(K13>0,1-I13/K13,0) -> 0
A14: Seedance 2.5 | B14: GASIC中转 | C14: doubao-seedance-2-5-260628 | D14: 720p | E14: 任意 | F14: — | G14: 按条 | H14: — | I14: =VLOOKUP("seedance-2.5|GASIC中转|任意",费率与参数!$A$16:$G$36,6,0) -> 2 | J14: =MAX(费率与参数!$B$4,CEILING(I14/费率与参数!$B$2,费率与参数!$B$3)) -> 200 | K14: =J14*费率与参数!$B$2 -> 2 | L14: =IF(K14>0,1-I14/K14,0) -> 0
A15: Seedance 2.5 | B15: GASIC中转 | C15: doubao-seedance-2-5-260628 | D15: 720p | E15: 任意 | F15: — | G15: 按条 | H15: — | I15: =VLOOKUP("seedance-2.5|GASIC中转|任意",费率与参数!$A$16:$G$36,6,0) -> 2 | J15: =MAX(费率与参数!$B$4,CEILING(I15/费率与参数!$B$2,费率与参数!$B$3)) -> 200 | K15: =J15*费率与参数!$B$2 -> 2 | L15: =IF(K15>0,1-I15/K15,0) -> 0
A16: Seedance 2.5 | B16: GASIC中转 | C16: doubao-seedance-2-5-260628 | D16: 1080p | E16: 任意 | F16: — | G16: 按条 | H16: — | I16: =VLOOKUP("seedance-2.5|GASIC中转|任意",费率与参数!$A$16:$G$36,6,0) -> 2 | J16: =MAX(费率与参数!$B$4,CEILING(I16/费率与参数!$B$2,费率与参数!$B$3)) -> 200 | K16: =J16*费率与参数!$B$2 -> 2 | L16: =IF(K16>0,1-I16/K16,0) -> 0
A17: Seedance 2.5 | B17: GASIC中转 | C17: doubao-seedance-2-5-260628 | D17: 1080p | E17: 任意 | F17: — | G17: 按条 | H17: — | I17: =VLOOKUP("seedance-2.5|GASIC中转|任意",费率与参数!$A$16:$G$36,6,0) -> 2 | J17: =MAX(费率与参数!$B$4,CEILING(I17/费率与参数!$B$2,费率与参数!$B$3)) -> 200 | K17: =J17*费率与参数!$B$2 -> 2 | L17: =IF(K17>0,1-I17/K17,0) -> 0
A18: Seedance 2.5 | B18: GASIC中转 | C18: doubao-seedance-2-5-260628 | D18: 1080p | E18: 任意 | F18: — | G18: 按条 | H18: — | I18: =VLOOKUP("seedance-2.5|GASIC中转|任意",费率与参数!$A$16:$G$36,6,0) -> 2 | J18: =MAX(费率与参数!$B$4,CEILING(I18/费率与参数!$B$2,费率与参数!$B$3)) -> 200 | K18: =J18*费率与参数!$B$2 -> 2 | L18: =IF(K18>0,1-I18/K18,0) -> 0
A19: Seedance 2.0 | B19: Ark官方 | C19: doubao-seedance-2-0-260128 | D19: 480p | E19: 5 | F19: — | G19: token | H19: =ROUNDUP(E19*VLOOKUP(D19,费率与参数!$A$10:$D$12,2,0)*VLOOKUP(D19,费率与参数!$A$10:$D$12,3,0)*VLOOKUP(D19,费率与参数!$A$10:$D$12,4,0)/1024,0) -> 48038 | I19: =H19*VLOOKUP("seedance-2.0|Ark官方|480p",费率与参数!$A$16:$G$36,6,0)/1000000 -> 1.44114 | J19: =MAX(费率与参数!$B$4,CEILING(I19/费率与参数!$B$2,费率与参数!$B$3)) -> 145 | K19: =J19*费率与参数!$B$2 -> 1.45 | L19: =IF(K19>0,1-I19/K19,0) -> 0.0061103448
A20: Seedance 2.0 | B20: Ark官方 | C20: doubao-seedance-2-0-260128 | D20: 480p | E20: 10 | F20: — | G20: token | H20: =ROUNDUP(E20*VLOOKUP(D20,费率与参数!$A$10:$D$12,2,0)*VLOOKUP(D20,费率与参数!$A$10:$D$12,3,0)*VLOOKUP(D20,费率与参数!$A$10:$D$12,4,0)/1024,0) -> 96075 | I20: =H20*VLOOKUP("seedance-2.0|Ark官方|480p",费率与参数!$A$16:$G$36,6,0)/1000000 -> 2.88225 | J20: =MAX(费率与参数!$B$4,CEILING(I20/费率与参数!$B$2,费率与参数!$B$3)) -> 289 | K20: =J20*费率与参数!$B$2 -> 2.89 | L20: =IF(K20>0,1-I20/K20,0) -> 0.0026816609
A21: Seedance 2.0 | B21: Ark官方 | C21: doubao-seedance-2-0-260128 | D21: 720p | E21: 5 | F21: — | G21: token | H21: =ROUNDUP(E21*VLOOKUP(D21,费率与参数!$A$10:$D$12,2,0)*VLOOKUP(D21,费率与参数!$A$10:$D$12,3,0)*VLOOKUP(D21,费率与参数!$A$10:$D$12,4,0)/1024,0) -> 108000 | I21: =H21*VLOOKUP("seedance-2.0|Ark官方|720p",费率与参数!$A$16:$G$36,6,0)/1000000 -> 4.86 | J21: =MAX(费率与参数!$B$4,CEILING(I21/费率与参数!$B$2,费率与参数!$B$3)) -> 486 | K21: =J21*费率与参数!$B$2 -> 4.86 | L21: =IF(K21>0,1-I21/K21,0) -> 0
A22: Seedance 2.0 | B22: Ark官方 | C22: doubao-seedance-2-0-260128 | D22: 720p | E22: 10 | F22: — | G22: token | H22: =ROUNDUP(E22*VLOOKUP(D22,费率与参数!$A$10:$D$12,2,0)*VLOOKUP(D22,费率与参数!$A$10:$D$12,3,0)*VLOOKUP(D22,费率与参数!$A$10:$D$12,4,0)/1024,0) -> 216000 | I22: =H22*VLOOKUP("seedance-2.0|Ark官方|720p",费率与参数!$A$16:$G$36,6,0)/1000000 -> 9.72 | J22: =MAX(费率与参数!$B$4,CEILING(I22/费率与参数!$B$2,费率与参数!$B$3)) -> 972 | K22: =J22*费率与参数!$B$2 -> 9.72 | L22: =IF(K22>0,1-I22/K22,0) -> 0
A23: Seedance 2.0 | B23: Ark官方 | C23: doubao-seedance-2-0-260128 | D23: 1080p | E23: 5 | F23: — | G23: token | H23: =ROUNDUP(E23*VLOOKUP(D23,费率与参数!$A$10:$D$12,2,0)*VLOOKUP(D23,费率与参数!$A$10:$D$12,3,0)*VLOOKUP(D23,费率与参数!$A$10:$D$12,4,0)/1024,0) -> 243000 | I23: =H23*VLOOKUP("seedance-2.0|Ark官方|1080p",费率与参数!$A$16:$G$36,6,0)/1000000 -> 18.225 | J23: =MAX(费率与参数!$B$4,CEILING(I23/费率与参数!$B$2,费率与参数!$B$3)) -> 1823 | K23: =J23*费率与参数!$B$2 -> 18.23 | L23: =IF(K23>0,1-I23/K23,0) -> 0.00027427318
A24: Seedance 2.0 | B24: Ark官方 | C24: doubao-seedance-2-0-260128 | D24: 1080p | E24: 10 | F24: — | G24: token | H24: =ROUNDUP(E24*VLOOKUP(D24,费率与参数!$A$10:$D$12,2,0)*VLOOKUP(D24,费率与参数!$A$10:$D$12,3,0)*VLOOKUP(D24,费率与参数!$A$10:$D$12,4,0)/1024,0) -> 486000 | I24: =H24*VLOOKUP("seedance-2.0|Ark官方|1080p",费率与参数!$A$16:$G$36,6,0)/1000000 -> 36.45 | J24: =MAX(费率与参数!$B$4,CEILING(I24/费率与参数!$B$2,费率与参数!$B$3)) -> 3645 | K24: =J24*费率与参数!$B$2 -> 36.45 | L24: =IF(K24>0,1-I24/K24,0) -> 0
A25: Seedance 2.0 | B25: GASIC中转 | C25: doubao-seedance-2-0-260128 | D25: 480p | E25: 任意 | F25: — | G25: 按条 | H25: — | I25: =VLOOKUP("seedance-2.0|GASIC中转|任意",费率与参数!$A$16:$G$36,6,0) -> 2 | J25: =MAX(费率与参数!$B$4,CEILING(I25/费率与参数!$B$2,费率与参数!$B$3)) -> 200 | K25: =J25*费率与参数!$B$2 -> 2 | L25: =IF(K25>0,1-I25/K25,0) -> 0
A26: Seedance 2.0 | B26: GASIC中转 | C26: doubao-seedance-2-0-260128 | D26: 480p | E26: 任意 | F26: — | G26: 按条 | H26: — | I26: =VLOOKUP("seedance-2.0|GASIC中转|任意",费率与参数!$A$16:$G$36,6,0) -> 2 | J26: =MAX(费率与参数!$B$4,CEILING(I26/费率与参数!$B$2,费率与参数!$B$3)) -> 200 | K26: =J26*费率与参数!$B$2 -> 2 | L26: =IF(K26>0,1-I26/K26,0) -> 0
A27: Seedance 2.0 | B27: GASIC中转 | C27: doubao-seedance-2-0-260128 | D27: 720p | E27: 任意 | F27: — | G27: 按条 | H27: — | I27: =VLOOKUP("seedance-2.0|GASIC中转|任意",费率与参数!$A$16:$G$36,6,0) -> 2 | J27: =MAX(费率与参数!$B$4,CEILING(I27/费率与参数!$B$2,费率与参数!$B$3)) -> 200 | K27: =J27*费率与参数!$B$2 -> 2 | L27: =IF(K27>0,1-I27/K27,0) -> 0
A28: Seedance 2.0 | B28: GASIC中转 | C28: doubao-seedance-2-0-260128 | D28: 720p | E28: 任意 | F28: — | G28: 按条 | H28: — | I28: =VLOOKUP("seedance-2.0|GASIC中转|任意",费率与参数!$A$16:$G$36,6,0) -> 2 | J28: =MAX(费率与参数!$B$4,CEILING(I28/费率与参数!$B$2,费率与参数!$B$3)) -> 200 | K28: =J28*费率与参数!$B$2 -> 2 | L28: =IF(K28>0,1-I28/K28,0) -> 0
A29: Seedance 2.0 | B29: GASIC中转 | C29: doubao-seedance-2-0-260128 | D29: 1080p | E29: 任意 | F29: — | G29: 按条 | H29: — | I29: =VLOOKUP("seedance-2.0|GASIC中转|任意",费率与参数!$A$16:$G$36,6,0) -> 2 | J29: =MAX(费率与参数!$B$4,CEILING(I29/费率与参数!$B$2,费率与参数!$B$3)) -> 200 | K29: =J29*费率与参数!$B$2 -> 2 | L29: =IF(K29>0,1-I29/K29,0) -> 0
A30: Seedance 2.0 | B30: GASIC中转 | C30: doubao-seedance-2-0-260128 | D30: 1080p | E30: 任意 | F30: — | G30: 按条 | H30: — | I30: =VLOOKUP("seedance-2.0|GASIC中转|任意",费率与参数!$A$16:$G$36,6,0) -> 2 | J30: =MAX(费率与参数!$B$4,CEILING(I30/费率与参数!$B$2,费率与参数!$B$3)) -> 200 | K30: =J30*费率与参数!$B$2 -> 2 | L30: =IF(K30>0,1-I30/K30,0) -> 0
A31: Seedance 2.0 Mini（极速版） | B31: Ark官方 | C31: doubao-seedance-2-0-mini-260615 | D31: 480p | E31: 4 | F31: — | G31: token | H31: =ROUNDUP(E31*VLOOKUP(D31,费率与参数!$A$10:$D$12,2,0)*VLOOKUP(D31,费率与参数!$A$10:$D$12,3,0)*VLOOKUP(D31,费率与参数!$A$10:$D$12,4,0)/1024,0) -> 38430 | I31: =H31*VLOOKUP("seedance-2.0-mini|Ark官方|480p",费率与参数!$A$16:$G$36,6,0)/1000000 -> 0.46116 | J31: =MAX(费率与参数!$B$4,CEILING(I31/费率与参数!$B$2,费率与参数!$B$3)) -> 47 | K31: =J31*费率与参数!$B$2 -> 0.47 | L31: =IF(K31>0,1-I31/K31,0) -> 0.018808511
A32: Seedance 2.0 Mini（极速版） | B32: Ark官方 | C32: doubao-seedance-2-0-mini-260615 | D32: 480p | E32: 5 | F32: — | G32: token | H32: =ROUNDUP(E32*VLOOKUP(D32,费率与参数!$A$10:$D$12,2,0)*VLOOKUP(D32,费率与参数!$A$10:$D$12,3,0)*VLOOKUP(D32,费率与参数!$A$10:$D$12,4,0)/1024,0) -> 48038 | I32: =H32*VLOOKUP("seedance-2.0-mini|Ark官方|480p",费率与参数!$A$16:$G$36,6,0)/1000000 -> 0.576456 | J32: =MAX(费率与参数!$B$4,CEILING(I32/费率与参数!$B$2,费率与参数!$B$3)) -> 58 | K32: =J32*费率与参数!$B$2 -> 0.58 | L32: =IF(K32>0,1-I32/K32,0) -> 0.0061103448
A33: Seedance 2.0 Mini（极速版） | B33: Ark官方 | C33: doubao-seedance-2-0-mini-260615 | D33: 480p | E33: 6 | F33: — | G33: token | H33: =ROUNDUP(E33*VLOOKUP(D33,费率与参数!$A$10:$D$12,2,0)*VLOOKUP(D33,费率与参数!$A$10:$D$12,3,0)*VLOOKUP(D33,费率与参数!$A$10:$D$12,4,0)/1024,0) -> 57645 | I33: =H33*VLOOKUP("seedance-2.0-mini|Ark官方|480p",费率与参数!$A$16:$G$36,6,0)/1000000 -> 0.69174 | J33: =MAX(费率与参数!$B$4,CEILING(I33/费率与参数!$B$2,费率与参数!$B$3)) -> 70 | K33: =J33*费率与参数!$B$2 -> 0.7 | L33: =IF(K33>0,1-I33/K33,0) -> 0.0118
A34: Seedance 2.0 Mini（极速版） | B34: Ark官方 | C34: doubao-seedance-2-0-mini-260615 | D34: 480p | E34: 7 | F34: — | G34: token | H34: =ROUNDUP(E34*VLOOKUP(D34,费率与参数!$A$10:$D$12,2,0)*VLOOKUP(D34,费率与参数!$A$10:$D$12,3,0)*VLOOKUP(D34,费率与参数!$A$10:$D$12,4,0)/1024,0) -> 67253 | I34: =H34*VLOOKUP("seedance-2.0-mini|Ark官方|480p",费率与参数!$A$16:$G$36,6,0)/1000000 -> 0.807036 | J34: =MAX(费率与参数!$B$4,CEILING(I34/费率与参数!$B$2,费率与参数!$B$3)) -> 81 | K34: =J34*费率与参数!$B$2 -> 0.81 | L34: =IF(K34>0,1-I34/K34,0) -> 0.0036592593
A35: Seedance 2.0 Mini（极速版） | B35: Ark官方 | C35: doubao-seedance-2-0-mini-260615 | D35: 480p | E35: 8 | F35: — | G35: token | H35: =ROUNDUP(E35*VLOOKUP(D35,费率与参数!$A$10:$D$12,2,0)*VLOOKUP(D35,费率与参数!$A$10:$D$12,3,0)*VLOOKUP(D35,费率与参数!$A$10:$D$12,4,0)/1024,0) -> 76860 | I35: =H35*VLOOKUP("seedance-2.0-mini|Ark官方|480p",费率与参数!$A$16:$G$36,6,0)/1000000 -> 0.92232 | J35: =MAX(费率与参数!$B$4,CEILING(I35/费率与参数!$B$2,费率与参数!$B$3)) -> 93 | K35: =J35*费率与参数!$B$2 -> 0.93 | L35: =IF(K35>0,1-I35/K35,0) -> 0.0082580645
A36: Seedance 2.0 Mini（极速版） | B36: Ark官方 | C36: doubao-seedance-2-0-mini-260615 | D36: 480p | E36: 9 | F36: — | G36: token | H36: =ROUNDUP(E36*VLOOKUP(D36,费率与参数!$A$10:$D$12,2,0)*VLOOKUP(D36,费率与参数!$A$10:$D$12,3,0)*VLOOKUP(D36,费率与参数!$A$10:$D$12,4,0)/1024,0) -> 86468 | I36: =H36*VLOOKUP("seedance-2.0-mini|Ark官方|480p",费率与参数!$A$16:$G$36,6,0)/1000000 -> 1.037616 | J36: =MAX(费率与参数!$B$4,CEILING(I36/费率与参数!$B$2,费率与参数!$B$3)) -> 104 | K36: =J36*费率与参数!$B$2 -> 1.04 | L36: =IF(K36>0,1-I36/K36,0) -> 0.0022923077
A37: Seedance 2.0 Mini（极速版） | B37: Ark官方 | C37: doubao-seedance-2-0-mini-260615 | D37: 480p | E37: 10 | F37: — | G37: token | H37: =ROUNDUP(E37*VLOOKUP(D37,费率与参数!$A$10:$D$12,2,0)*VLOOKUP(D37,费率与参数!$A$10:$D$12,3,0)*VLOOKUP(D37,费率与参数!$A$10:$D$12,4,0)/1024,0) -> 96075 | I37: =H37*VLOOKUP("seedance-2.0-mini|Ark官方|480p",费率与参数!$A$16:$G$36,6,0)/1000000 -> 1.1529 | J37: =MAX(费率与参数!$B$4,CEILING(I37/费率与参数!$B$2,费率与参数!$B$3)) -> 116 | K37: =J37*费率与参数!$B$2 -> 1.16 | L37: =IF(K37>0,1-I37/K37,0) -> 0.0061206897
A38: Seedance 2.0 Mini（极速版） | B38: Ark官方 | C38: doubao-seedance-2-0-mini-260615 | D38: 480p | E38: 11 | F38: — | G38: token | H38: =ROUNDUP(E38*VLOOKUP(D38,费率与参数!$A$10:$D$12,2,0)*VLOOKUP(D38,费率与参数!$A$10:$D$12,3,0)*VLOOKUP(D38,费率与参数!$A$10:$D$12,4,0)/1024,0) -> 105683 | I38: =H38*VLOOKUP("seedance-2.0-mini|Ark官方|480p",费率与参数!$A$16:$G$36,6,0)/1000000 -> 1.268196 | J38: =MAX(费率与参数!$B$4,CEILING(I38/费率与参数!$B$2,费率与参数!$B$3)) -> 127 | K38: =J38*费率与参数!$B$2 -> 1.27 | L38: =IF(K38>0,1-I38/K38,0) -> 0.0014204724
A39: Seedance 2.0 Mini（极速版） | B39: Ark官方 | C39: doubao-seedance-2-0-mini-260615 | D39: 480p | E39: 12 | F39: — | G39: token | H39: =ROUNDUP(E39*VLOOKUP(D39,费率与参数!$A$10:$D$12,2,0)*VLOOKUP(D39,费率与参数!$A$10:$D$12,3,0)*VLOOKUP(D39,费率与参数!$A$10:$D$12,4,0)/1024,0) -> 115290 | I39: =H39*VLOOKUP("seedance-2.0-mini|Ark官方|480p",费率与参数!$A$16:$G$36,6,0)/1000000 -> 1.38348 | J39: =MAX(费率与参数!$B$4,CEILING(I39/费率与参数!$B$2,费率与参数!$B$3)) -> 139 | K39: =J39*费率与参数!$B$2 -> 1.39 | L39: =IF(K39>0,1-I39/K39,0) -> 0.0046906475
A40: Seedance 2.0 Mini（极速版） | B40: Ark官方 | C40: doubao-seedance-2-0-mini-260615 | D40: 480p | E40: 13 | F40: — | G40: token | H40: =ROUNDUP(E40*VLOOKUP(D40,费率与参数!$A$10:$D$12,2,0)*VLOOKUP(D40,费率与参数!$A$10:$D$12,3,0)*VLOOKUP(D40,费率与参数!$A$10:$D$12,4,0)/1024,0) -> 124898 | I40: =H40*VLOOKUP("seedance-2.0-mini|Ark官方|480p",费率与参数!$A$16:$G$36,6,0)/1000000 -> 1.498776 | J40: =MAX(费率与参数!$B$4,CEILING(I40/费率与参数!$B$2,费率与参数!$B$3)) -> 150 | K40: =J40*费率与参数!$B$2 -> 1.5 | L40: =IF(K40>0,1-I40/K40,0) -> 0.000816
A41: Seedance 2.0 Mini（极速版） | B41: Ark官方 | C41: doubao-seedance-2-0-mini-260615 | D41: 480p | E41: 14 | F41: — | G41: token | H41: =ROUNDUP(E41*VLOOKUP(D41,费率与参数!$A$10:$D$12,2,0)*VLOOKUP(D41,费率与参数!$A$10:$D$12,3,0)*VLOOKUP(D41,费率与参数!$A$10:$D$12,4,0)/1024,0) -> 134505 | I41: =H41*VLOOKUP("seedance-2.0-mini|Ark官方|480p",费率与参数!$A$16:$G$36,6,0)/1000000 -> 1.61406 | J41: =MAX(费率与参数!$B$4,CEILING(I41/费率与参数!$B$2,费率与参数!$B$3)) -> 162 | K41: =J41*费率与参数!$B$2 -> 1.62 | L41: =IF(K41>0,1-I41/K41,0) -> 0.0036666667
...

Sheet 建议售价清单
A1: 建议售价清单（毛利率按“低参数 50%~100%、高参数 30%~50%”自动插值；H 列可手改单个毛利率，其余自动重算）
A3: 路由 | B3: 渠道 | C3: 模型 | D3: 分辨率 | E3: 时长(秒) | F3: 输入视频秒 | G3: 成本(元) | H3: 目标毛利率 | I3: 建议售价(元) | J3: 建议售价(积分) | K3: 实际毛利率 | L3: 现售价(积分) | M3: 涨幅
A4: Seedance 2.5 | B4: Ark官方 | C4: doubao-seedance-2-5-260628 | D4: 480p | E4: 5 | F4: — | G4: =成本与现售价!$I$4 -> 2.88228 | H4: =MIN(0.95,MAX(费率与参数!$B$6,费率与参数!$B$5-(费率与参数!$B$5-费率与参数!$B$6)*(LN(MAX(G4,0.01))-LN(MIN(成本与现售价!$I$4:$I$172)))/(LN(MAX(成本与现售价!$I$4:$I$172))-LN(MIN(成本与现售价!$I$4:$I$172))))) -> 0.37331728 | I4: =CEILING(G4/(1-H4)/费率与参数!$B$2,费率与参数!$B$3)*费率与参数!$B$2 -> 4.6 | J4: =I4/费率与参数!$B$2 -> 460 | K4: =1-G4/I4 -> 0.37341739 | L4: =成本与现售价!$J$4 -> 289 | M4: =I4/成本与现售价!$K$4-1 -> 0.5916955
A5: Seedance 2.5 | B5: Ark官方 | C5: doubao-seedance-2-5-260628 | D5: 480p | E5: 10 | F5: — | G5: =成本与现售价!$I$5 -> 5.7645 | H5: =MIN(0.95,MAX(费率与参数!$B$6,费率与参数!$B$5-(费率与参数!$B$5-费率与参数!$B$6)*(LN(MAX(G5,0.01))-LN(MIN(成本与现售价!$I$4:$I$172)))/(LN(MAX(成本与现售价!$I$4:$I$172))-LN(MIN(成本与现售价!$I$4:$I$172))))) -> 0.32540238 | I5: =CEILING(G5/(1-H5)/费率与参数!$B$2,费率与参数!$B$3)*费率与参数!$B$2 -> 8.55 | J5: =I5/费率与参数!$B$2 -> 855 | K5: =1-G5/I5 -> 0.32578947 | L5: =成本与现售价!$J$5 -> 577 | M5: =I5/成本与现售价!$K$5-1 -> 0.48180243
A6: Seedance 2.5 | B6: Ark官方 | C6: doubao-seedance-2-5-260628 | D6: 720p | E6: 5 | F6: — | G6: =成本与现售价!$I$6 -> 9.72 | H6: =MIN(0.95,MAX(费率与参数!$B$6,费率与参数!$B$5-(费率与参数!$B$5-费率与参数!$B$6)*(LN(MAX(G6,0.01))-LN(MIN(成本与现售价!$I$4:$I$172)))/(LN(MAX(成本与现售价!$I$4:$I$172))-LN(MIN(成本与现售价!$I$4:$I$172))))) -> 0.28928546 | I6: =CEILING(G6/(1-H6)/费率与参数!$B$2,费率与参数!$B$3)*费率与参数!$B$2 -> 13.68 | J6: =I6/费率与参数!$B$2 -> 1368 | K6: =1-G6/I6 -> 0.28947368 | L6: =成本与现售价!$J$6 -> 972 | M6: =I6/成本与现售价!$K$6-1 -> 0.40740741
A7: Seedance 2.5 | B7: Ark官方 | C7: doubao-seedance-2-5-260628 | D7: 720p | E7: 10 | F7: — | G7: =成本与现售价!$I$7 -> 19.44 | H7: =MIN(0.95,MAX(费率与参数!$B$6,费率与参数!$B$5-(费率与参数!$B$5-费率与参数!$B$6)*(LN(MAX(G7,0.01))-LN(MIN(成本与现售价!$I$4:$I$172)))/(LN(MAX(成本与现售价!$I$4:$I$172))-LN(MIN(成本与现售价!$I$4:$I$172))))) -> 0.24136984 | I7: =CEILING(G7/(1-H7)/费率与参数!$B$2,费率与参数!$B$3)*费率与参数!$B$2 -> 25.63 | J7: =I7/费率与参数!$B$2 -> 2563 | K7: =1-G7/I7 -> 0.24151385 | L7: =成本与现售价!$J$7 -> 1944 | M7: =I7/成本与现售价!$K$7-1 -> 0.31841564
A8: Seedance 2.5 | B8: Ark官方 | C8: doubao-seedance-2-5-260628 | D8: 1080p | E8: 5 | F8: — | G8: =成本与现售价!$I$8 -> 36.45 | H8: =MIN(0.95,MAX(费率与参数!$B$6,费率与参数!$B$5-(费率与参数!$B$5-费率与参数!$B$6)*(LN(MAX(G8,0.01))-LN(MIN(成本与现售价!$I$4:$I$172)))/(LN(MAX(成本与现售价!$I$4:$I$172))-LN(MIN(成本与现售价!$I$4:$I$172))))) -> 0.19791562 | I8: =CEILING(G8/(1-H8)/费率与参数!$B$2,费率与参数!$B$3)*费率与参数!$B$2 -> 45.45 | J8: =I8/费率与参数!$B$2 -> 4545 | K8: =1-G8/I8 -> 0.1980198 | L8: =成本与现售价!$J$8 -> 3645 | M8: =I8/成本与现售价!$K$8-1 -> 0.24691358
A9: Seedance 2.5 | B9: Ark官方 | C9: doubao-seedance-2-5-260628 | D9: 1080p | E9: 10 | F9: — | G9: =成本与现售价!$I$9 -> 72.9 | H9: =MIN(0.95,MAX(费率与参数!$B$6,费率与参数!$B$5-(费率与参数!$B$5-费率与参数!$B$6)*(LN(MAX(G9,0.01))-LN(MIN(成本与现售价!$I$4:$I$172)))/(LN(MAX(成本与现售价!$I$4:$I$172))-LN(MIN(成本与现售价!$I$4:$I$172))))) -> 0.15 | I9: =CEILING(G9/(1-H9)/费率与参数!$B$2,费率与参数!$B$3)*费率与参数!$B$2 -> 85.77 | J9: =I9/费率与参数!$B$2 -> 8577 | K9: =1-G9/I9 -> 0.15005247 | L9: =成本与现售价!$J$9 -> 7290 | M9: =I9/成本与现售价!$K$9-1 -> 0.17654321
A10: Seedance 2.5 | B10: GASIC中转 | C10: doubao-seedance-2-5-260628 | D10: 480p | E10: 4 | F10: — | G10: =成本与现售价!$I$10 -> 2 | H10: =MIN(0.95,MAX(费率与参数!$B$6,费率与参数!$B$5-(费率与参数!$B$5-费率与参数!$B$6)*(LN(MAX(G10,0.01))-LN(MIN(成本与现售价!$I$4:$I$172)))/(LN(MAX(成本与现售价!$I$4:$I$172))-LN(MIN(成本与现售价!$I$4:$I$172))))) -> 0.39857889 | I10: =CEILING(G10/(1-H10)/费率与参数!$B$2,费率与参数!$B$3)*费率与参数!$B$2 -> 3.33 | J10: =I10/费率与参数!$B$2 -> 333 | K10: =1-G10/I10 -> 0.3993994 | L10: =成本与现售价!$J$10 -> 200 | M10: =I10/成本与现售价!$K$10-1 -> 0.665
A11: Seedance 2.5 | B11: GASIC中转 | C11: doubao-seedance-2-5-260628 | D11: 480p | E11: 10 | F11: — | G11: =成本与现售价!$I$11 -> 2 | H11: =MIN(0.95,MAX(费率与参数!$B$6,费率与参数!$B$5-(费率与参数!$B$5-费率与参数!$B$6)*(LN(MAX(G11,0.01))-LN(MIN(成本与现售价!$I$4:$I$172)))/(LN(MAX(成本与现售价!$I$4:$I$172))-LN(MIN(成本与现售价!$I$4:$I$172))))) -> 0.39857889 | I11: =CEILING(G11/(1-H11)/费率与参数!$B$2,费率与参数!$B$3)*费率与参数!$B$2 -> 3.33 | J11: =I11/费率与参数!$B$2 -> 333 | K11: =1-G11/I11 -> 0.3993994 | L11: =成本与现售价!$J$11 -> 200 | M11: =I11/成本与现售价!$K$11-1 -> 0.665
A12: Seedance 2.5 | B12: GASIC中转 | C12: doubao-seedance-2-5-260628 | D12: 480p | E12: 20 | F12: — | G12: =成本与现售价!$I$12 -> 2 | H12: =MIN(0.95,MAX(费率与参数!$B$6,费率与参数!$B$5-(费率与参数!$B$5-费率与参数!$B$6)*(LN(MAX(G12,0.01))-LN(MIN(成本与现售价!$I$4:$I$172)))/(LN(MAX(成本与现售价!$I$4:$I$172))-LN(MIN(成本与现售价!$I$4:$I$172))))) -> 0.39857889 | I12: =CEILING(G12/(1-H12)/费率与参数!$B$2,费率与参数!$B$3)*费率与参数!$B$2 -> 3.33 | J12: =I12/费率与参数!$B$2 -> 333 | K12: =1-G12/I12 -> 0.3993994 | L12: =成本与现售价!$J$12 -> 200 | M12: =I12/成本与现售价!$K$12-1 -> 0.665
A13: Seedance 2.5 | B13: GASIC中转 | C13: doubao-seedance-2-5-260628 | D13: 720p | E13: 4 | F13: — | G13: =成本与现售价!$I$13 -> 2 | H13: =MIN(0.95,MAX(费率与参数!$B$6,费率与参数!$B$5-(费率与参数!$B$5-费率与参数!$B$6)*(LN(MAX(G13,0.01))-LN(MIN(成本与现售价!$I$4:$I$172)))/(LN(MAX(成本与现售价!$I$4:$I$172))-LN(MIN(成本与现售价!$I$4:$I$172))))) -> 0.39857889 | I13: =CEILING(G13/(1-H13)/费率与参数!$B$2,费率与参数!$B$3)*费率与参数!$B$2 -> 3.33 | J13: =I13/费率与参数!$B$2 -> 333 | K13: =1-G13/I13 -> 0.3993994 | L13: =成本与现售价!$J$13 -> 200 | M13: =I13/成本与现售价!$K$13-1 -> 0.665
A14: Seedance 2.5 | B14: GASIC中转 | C14: doubao-seedance-2-5-260628 | D14: 720p | E14: 10 | F14: — | G14: =成本与现售价!$I$14 -> 2 | H14: =MIN(0.95,MAX(费率与参数!$B$6,费率与参数!$B$5-(费率与参数!$B$5-费率与参数!$B$6)*(LN(MAX(G14,0.01))-LN(MIN(成本与现售价!$I$4:$I$172)))/(LN(MAX(成本与现售价!$I$4:$I$172))-LN(MIN(成本与现售价!$I$4:$I$172))))) -> 0.39857889 | I14: =CEILING(G14/(1-H14)/费率与参数!$B$2,费率与参数!$B$3)*费率与参数!$B$2 -> 3.33 | J14: =I14/费率与参数!$B$2 -> 333 | K14: =1-G14/I14 -> 0.3993994 | L14: =成本与现售价!$J$14 -> 200 | M14: =I14/成本与现售价!$K$14-1 -> 0.665
A15: Seedance 2.5 | B15: GASIC中转 | C15: doubao-seedance-2-5-260628 | D15: 720p | E15: 20 | F15: — | G15: =成本与现售价!$I$15 -> 2 | H15: =MIN(0.95,MAX(费率与参数!$B$6,费率与参数!$B$5-(费率与参数!$B$5-费率与参数!$B$6)*(LN(MAX(G15,0.01))-LN(MIN(成本与现售价!$I$4:$I$172)))/(LN(MAX(成本与现售价!$I$4:$I$172))-LN(MIN(成本与现售价!$I$4:$I$172))))) -> 0.39857889 | I15: =CEILING(G15/(1-H15)/费率与参数!$B$2,费率与参数!$B$3)*费率与参数!$B$2 -> 3.33 | J15: =I15/费率与参数!$B$2 -> 333 | K15: =1-G15/I15 -> 0.3993994 | L15: =成本与现售价!$J$15 -> 200 | M15: =I15/成本与现售价!$K$15-1 -> 0.665
A16: Seedance 2.5 | B16: GASIC中转 | C16: doubao-seedance-2-5-260628 | D16: 1080p | E16: 4 | F16: — | G16: =成本与现售价!$I$16 -> 2 | H16: =MIN(0.95,MAX(费率与参数!$B$6,费率与参数!$B$5-(费率与参数!$B$5-费率与参数!$B$6)*(LN(MAX(G16,0.01))-LN(MIN(成本与现售价!$I$4:$I$172)))/(LN(MAX(成本与现售价!$I$4:$I$172))-LN(MIN(成本与现售价!$I$4:$I$172))))) -> 0.39857889 | I16: =CEILING(G16/(1-H16)/费率与参数!$B$2,费率与参数!$B$3)*费率与参数!$B$2 -> 3.33 | J16: =I16/费率与参数!$B$2 -> 333 | K16: =1-G16/I16 -> 0.3993994 | L16: =成本与现售价!$J$16 -> 200 | M16: =I16/成本与现售价!$K$16-1 -> 0.665
A17: Seedance 2.5 | B17: GASIC中转 | C17: doubao-seedance-2-5-260628 | D17: 1080p | E17: 10 | F17: — | G17: =成本与现售价!$I$17 -> 2 | H17: =MIN(0.95,MAX(费率与参数!$B$6,费率与参数!$B$5-(费率与参数!$B$5-费率与参数!$B$6)*(LN(MAX(G17,0.01))-LN(MIN(成本与现售价!$I$4:$I$172)))/(LN(MAX(成本与现售价!$I$4:$I$172))-LN(MIN(成本与现售价!$I$4:$I$172))))) -> 0.39857889 | I17: =CEILING(G17/(1-H17)/费率与参数!$B$2,费率与参数!$B$3)*费率与参数!$B$2 -> 3.33 | J17: =I17/费率与参数!$B$2 -> 333 | K17: =1-G17/I17 -> 0.3993994 | L17: =成本与现售价!$J$17 -> 200 | M17: =I17/成本与现售价!$K$17-1 -> 0.665
A18: Seedance 2.5 | B18: GASIC中转 | C18: doubao-seedance-2-5-260628 | D18: 1080p | E18: 20 | F18: — | G18: =成本与现售价!$I$18 -> 2 | H18: =MIN(0.95,MAX(费率与参数!$B$6,费率与参数!$B$5-(费率与参数!$B$5-费率与参数!$B$6)*(LN(MAX(G18,0.01))-LN(MIN(成本与现售价!$I$4:$I$172)))/(LN(MAX(成本与现售价!$I$4:$I$172))-LN(MIN(成本与现售价!$I$4:$I$172))))) -> 0.39857889 | I18: =CEILING(G18/(1-H18)/费率与参数!$B$2,费率与参数!$B$3)*费率与参数!$B$2 -> 3.33 | J18: =I18/费率与参数!$B$2 -> 333 | K18: =1-G18/I18 -> 0.3993994 | L18: =成本与现售价!$J$18 -> 200 | M18: =I18/成本与现售价!$K$18-1 -> 0.665
A19: Seedance 2.0 | B19: Ark官方 | C19: doubao-seedance-2-0-260128 | D19: 480p | E19: 5 | F19: — | G19: =成本与现售价!$I$19 -> 1.44114 | H19: =MIN(0.95,MAX(费率与参数!$B$6,费率与参数!$B$5-(费率与参数!$B$5-费率与参数!$B$6)*(LN(MAX(G19,0.01))-LN(MIN(成本与现售价!$I$4:$I$172)))/(LN(MAX(成本与现售价!$I$4:$I$172))-LN(MIN(成本与现售价!$I$4:$I$172))))) -> 0.42123289 | I19: =CEILING(G19/(1-H19)/费率与参数!$B$2,费率与参数!$B$3)*费率与参数!$B$2 -> 2.5 | J19: =I19/费率与参数!$B$2 -> 250 | K19: =1-G19/I19 -> 0.423544 | L19: =成本与现售价!$J$19 -> 145 | M19: =I19/成本与现售价!$K$19-1 -> 0.72413793
A20: Seedance 2.0 | B20: Ark官方 | C20: doubao-seedance-2-0-260128 | D20: 480p | E20: 10 | F20: — | G20: =成本与现售价!$I$20 -> 2.88225 | H20: =MIN(0.95,MAX(费率与参数!$B$6,费率与参数!$B$5-(费率与参数!$B$5-费率与参数!$B$6)*(LN(MAX(G20,0.01))-LN(MIN(成本与现售价!$I$4:$I$172)))/(LN(MAX(成本与现售价!$I$4:$I$172))-LN(MIN(成本与现售价!$I$4:$I$172))))) -> 0.373318 | I20: =CEILING(G20/(1-H20)/费率与参数!$B$2,费率与参数!$B$3)*费率与参数!$B$2 -> 4.6 | J20: =I20/费率与参数!$B$2 -> 460 | K20: =1-G20/I20 -> 0.37342391 | L20: =成本与现售价!$J$20 -> 289 | M20: =I20/成本与现售价!$K$20-1 -> 0.5916955
A21: Seedance 2.0 | B21: Ark官方 | C21: doubao-seedance-2-0-260128 | D21: 720p | E21: 5 | F21: — | G21: =成本与现售价!$I$21 -> 4.86 | H21: =MIN(0.95,MAX(费率与参数!$B$6,费率与参数!$B$5-(费率与参数!$B$5-费率与参数!$B$6)*(LN(MAX(G21,0.01))-LN(MIN(成本与现售价!$I$4:$I$172)))/(LN(MAX(成本与现售价!$I$4:$I$172))-LN(MIN(成本与现售价!$I$4:$I$172))))) -> 0.33720108 | I21: =CEILING(G21/(1-H21)/费率与参数!$B$2,费率与参数!$B$3)*费率与参数!$B$2 -> 7.34 | J21: =I21/费率与参数!$B$2 -> 734 | K21: =1-G21/I21 -> 0.33787466 | L21: =成本与现售价!$J$21 -> 486 | M21: =I21/成本与现售价!$K$21-1 -> 0.51028807
A22: Seedance 2.0 | B22: Ark官方 | C22: doubao-seedance-2-0-260128 | D22: 720p | E22: 10 | F22: — | G22: =成本与现售价!$I$22 -> 9.72 | H22: =MIN(0.95,MAX(费率与参数!$B$6,费率与参数!$B$5-(费率与参数!$B$5-费率与参数!$B$6)*(LN(MAX(G22,0.01))-LN(MIN(成本与现售价!$I$4:$I$172)))/(LN(MAX(成本与现售价!$I$4:$I$172))-LN(MIN(成本与现售价!$I$4:$I$172))))) -> 0.28928546 | I22: =CEILING(G22/(1-H22)/费率与参数!$B$2,费率与参数!$B$3)*费率与参数!$B$2 -> 13.68 | J22: =I22/费率与参数!$B$2 -> 1368 | K22: =1-G22/I22 -> 0.28947368 | L22: =成本与现售价!$J$22 -> 972 | M22: =I22/成本与现售价!$K$22-1 -> 0.40740741
A23: Seedance 2.0 | B23: Ark官方 | C23: doubao-seedance-2-0-260128 | D23: 1080p | E23: 5 | F23: — | G23: =成本与现售价!$I$23 -> 18.225 | H23: =MIN(0.95,MAX(费率与参数!$B$6,费率与参数!$B$5-(费率与参数!$B$5-费率与参数!$B$6)*(LN(MAX(G23,0.01))-LN(MIN(成本与现售价!$I$4:$I$172)))/(LN(MAX(成本与现售价!$I$4:$I$172))-LN(MIN(成本与现售价!$I$4:$I$172))))) -> 0.24583124 | I23: =CEILING(G23/(1-H23)/费率与参数!$B$2,费率与参数!$B$3)*费率与参数!$B$2 -> 24.17 | J23: =I23/费率与参数!$B$2 -> 2417 | K23: =1-G23/I23 -> 0.24596607 | L23: =成本与现售价!$J$23 -> 1823 | M23: =I23/成本与现售价!$K$23-1 -> 0.32583653
A24: Seedance 2.0 | B24: Ark官方 | C24: doubao-seedance-2-0-260128 | D24: 1080p | E24: 10 | F24: — | G24: =成本与现售价!$I$24 -> 36.45 | H24: =MIN(0.95,MAX(费率与参数!$B$6,费率与参数!$B$5-(费率与参数!$B$5-费率与参数!$B$6)*(LN(MAX(G24,0.01))-LN(MIN(成本与现售价!$I$4:$I$172)))/(LN(MAX(成本与现售价!$I$4:$I$172))-LN(MIN(成本与现售价!$I$4:$I$172))))) -> 0.19791562 | I24: =CEILING(G24/(1-H24)/费率与参数!$B$2,费率与参数!$B$3)*费率与参数!$B$2 -> 45.45 | J24: =I24/费率与参数!$B$2 -> 4545 | K24: =1-G24/I24 -> 0.1980198 | L24: =成本与现售价!$J$24 -> 3645 | M24: =I24/成本与现售价!$K$24-1 -> 0.24691358
A25: Seedance 2.0 | B25: GASIC中转 | C25: doubao-seedance-2-0-260128 | D25: 480p | E25: 4 | F25: — | G25: =成本与现售价!$I$25 -> 2 | H25: =MIN(0.95,MAX(费率与参数!$B$6,费率与参数!$B$5-(费率与参数!$B$5-费率与参数!$B$6)*(LN(MAX(G25,0.01))-LN(MIN(成本与现售价!$I$4:$I$172)))/(LN(MAX(成本与现售价!$I$4:$I$172))-LN(MIN(成本与现售价!$I$4:$I$172))))) -> 0.39857889 | I25: =CEILING(G25/(1-H25)/费率与参数!$B$2,费率与参数!$B$3)*费率与参数!$B$2 -> 3.33 | J25: =I25/费率与参数!$B$2 -> 333 | K25: =1-G25/I25 -> 0.3993994 | L25: =成本与现售价!$J$25 -> 200 | M25: =I25/成本与现售价!$K$25-1 -> 0.665
A26: Seedance 2.0 | B26: GASIC中转 | C26: doubao-seedance-2-0-260128 | D26: 480p | E26: 15 | F26: — | G26: =成本与现售价!$I$26 -> 2 | H26: =MIN(0.95,MAX(费率与参数!$B$6,费率与参数!$B$5-(费率与参数!$B$5-费率与参数!$B$6)*(LN(MAX(G26,0.01))-LN(MIN(成本与现售价!$I$4:$I$172)))/(LN(MAX(成本与现售价!$I$4:$I$172))-LN(MIN(成本与现售价!$I$4:$I$172))))) -> 0.39857889 | I26: =CEILING(G26/(1-H26)/费率与参数!$B$2,费率与参数!$B$3)*费率与参数!$B$2 -> 3.33 | J26: =I26/费率与参数!$B$2 -> 333 | K26: =1-G26/I26 -> 0.3993994 | L26: =成本与现售价!$J$26 -> 200 | M26: =I26/成本与现售价!$K$26-1 -> 0.665
A27: Seedance 2.0 | B27: GASIC中转 | C27: doubao-seedance-2-0-260128 | D27: 720p | E27: 4 | F27: — | G27: =成本与现售价!$I$27 -> 2 | H27: =MIN(0.95,MAX(费率与参数!$B$6,费率与参数!$B$5-(费率与参数!$B$5-费率与参数!$B$6)*(LN(MAX(G27,0.01))-LN(MIN(成本与现售价!$I$4:$I$172)))/(LN(MAX(成本与现售价!$I$4:$I$172))-LN(MIN(成本与现售价!$I$4:$I$172))))) -> 0.39857889 | I27: =CEILING(G27/(1-H27)/费率与参数!$B$2,费率与参数!$B$3)*费率与参数!$B$2 -> 3.33 | J27: =I27/费率与参数!$B$2 -> 333 | K27: =1-G27/I27 -> 0.3993994 | L27: =成本与现售价!$J$27 -> 200 | M27: =I27/成本与现售价!$K$27-1 -> 0.665
A28: Seedance 2.0 | B28: GASIC中转 | C28: doubao-seedance-2-0-260128 | D28: 720p | E28: 15 | F28: — | G28: =成本与现售价!$I$28 -> 2 | H28: =MIN(0.95,MAX(费率与参数!$B$6,费率与参数!$B$5-(费率与参数!$B$5-费率与参数!$B$6)*(LN(MAX(G28,0.01))-LN(MIN(成本与现售价!$I$4:$I$172)))/(LN(MAX(成本与现售价!$I$4:$I$172))-LN(MIN(成本与现售价!$I$4:$I$172))))) -> 0.39857889 | I28: =CEILING(G28/(1-H28)/费率与参数!$B$2,费率与参数!$B$3)*费率与参数!$B$2 -> 3.33 | J28: =I28/费率与参数!$B$2 -> 333 | K28: =1-G28/I28 -> 0.3993994 | L28: =成本与现售价!$J$28 -> 200 | M28: =I28/成本与现售价!$K$28-1 -> 0.665
A29: Seedance 2.0 | B29: GASIC中转 | C29: doubao-seedance-2-0-260128 | D29: 1080p | E29: 4 | F29: — | G29: =成本与现售价!$I$29 -> 2 | H29: =MIN(0.95,MAX(费率与参数!$B$6,费率与参数!$B$5-(费率与参数!$B$5-费率与参数!$B$6)*(LN(MAX(G29,0.01))-LN(MIN(成本与现售价!$I$4:$I$172)))/(LN(MAX(成本与现售价!$I$4:$I$172))-LN(MIN(成本与现售价!$I$4:$I$172))))) -> 0.39857889 | I29: =CEILING(G29/(1-H29)/费率与参数!$B$2,费率与参数!$B$3)*费率与参数!$B$2 -> 3.33 | J29: =I29/费率与参数!$B$2 -> 333 | K29: =1-G29/I29 -> 0.3993994 | L29: =成本与现售价!$J$29 -> 200 | M29: =I29/成本与现售价!$K$29-1 -> 0.665
A30: Seedance 2.0 | B30: GASIC中转 | C30: doubao-seedance-2-0-260128 | D30: 1080p | E30: 15 | F30: — | G30: =成本与现售价!$I$30 -> 2 | H30: =MIN(0.95,MAX(费率与参数!$B$6,费率与参数!$B$5-(费率与参数!$B$5-费率与参数!$B$6)*(LN(MAX(G30,0.01))-LN(MIN(成本与现售价!$I$4:$I$172)))/(LN(MAX(成本与现售价!$I$4:$I$172))-LN(MIN(成本与现售价!$I$4:$I$172))))) -> 0.39857889 | I30: =CEILING(G30/(1-H30)/费率与参数!$B$2,费率与参数!$B$3)*费率与参数!$B$2 -> 3.33 | J30: =I30/费率与参数!$B$2 -> 333 | K30: =1-G30/I30 -> 0.3993994 | L30: =成本与现售价!$J$30 -> 200 | M30: =I30/成本与现售价!$K$30-1 -> 0.665
A31: Seedance 2.0 Mini（极速版） | B31: Ark官方 | C31: doubao-seedance-2-0-mini-260615 | D31: 480p | E31: 4 | F31: — | G31: =成本与现售价!$I$31 -> 0.46116 | H31: =MIN(0.95,MAX(费率与参数!$B$6,费率与参数!$B$5-(费率与参数!$B$5-费率与参数!$B$6)*(LN(MAX(G31,0.01))-LN(MIN(成本与现售价!$I$4:$I$172)))/(LN(MAX(成本与现售价!$I$4:$I$172))-LN(MIN(成本与现售价!$I$4:$I$172))))) -> 0.5 | I31: =CEILING(G31/(1-H31)/费率与参数!$B$2,费率与参数!$B$3)*费率与参数!$B$2 -> 0.93 | J31: =I31/费率与参数!$B$2 -> 93 | K31: =1-G31/I31 -> 0.50412903 | L31: =成本与现售价!$J$31 -> 47 | M31: =I31/成本与现售价!$K$31-1 -> 0.9787234
A32: Seedance 2.0 Mini（极速版） | B32: Ark官方 | C32: doubao-seedance-2-0-mini-260615 | D32: 480p | E32: 5 | F32: — | G32: =成本与现售价!$I$32 -> 0.576456 | H32: =MIN(0.95,MAX(费率与参数!$B$6,费率与参数!$B$5-(费率与参数!$B$5-费率与参数!$B$6)*(LN(MAX(G32,0.01))-LN(MIN(成本与现售价!$I$4:$I$172)))/(LN(MAX(成本与现售价!$I$4:$I$172))-LN(MIN(成本与现售价!$I$4:$I$172))))) -> 0.4845739 | I32: =CEILING(G32/(1-H32)/费率与参数!$B$2,费率与参数!$B$3)*费率与参数!$B$2 -> 1.12 | J32: =I32/费率与参数!$B$2 -> 112 | K32: =1-G32/I32 -> 0.48530714 | L32: =成本与现售价!$J$32 -> 58 | M32: =I32/成本与现售价!$K$32-1 -> 0.93103448
A33: Seedance 2.0 Mini（极速版） | B33: Ark官方 | C33: doubao-seedance-2-0-mini-260615 | D33: 480p | E33: 6 | F33: — | G33: =成本与现售价!$I$33 -> 0.69174 | H33: =MIN(0.95,MAX(费率与参数!$B$6,费率与参数!$B$5-(费率与参数!$B$5-费率与参数!$B$6)*(LN(MAX(G33,0.01))-LN(MIN(成本与现售价!$I$4:$I$172)))/(LN(MAX(成本与现售价!$I$4:$I$172))-LN(MIN(成本与现售价!$I$4:$I$172))))) -> 0.47197116 | I33: =CEILING(G33/(1-H33)/费率与参数!$B$2,费率与参数!$B$3)*费率与参数!$B$2 -> 1.32 | J33: =I33/费率与参数!$B$2 -> 132 | K33: =1-G33/I33 -> 0.47595455 | L33: =成本与现售价!$J$33 -> 70 | M33: =I33/成本与现售价!$K$33-1 -> 0.88571429
A34: Seedance 2.0 Mini（极速版） | B34: Ark官方 | C34: doubao-seedance-2-0-mini-260615 | D34: 480p | E34: 7 | F34: — | G34: =成本与现售价!$I$34 -> 0.807036 | H34: =MIN(0.95,MAX(费率与参数!$B$6,费率与参数!$B$5-(费率与参数!$B$5-费率与参数!$B$6)*(LN(MAX(G34,0.01))-LN(MIN(成本与现售价!$I$4:$I$172)))/(LN(MAX(成本与现售价!$I$4:$I$172))-LN(MIN(成本与现售价!$I$4:$I$172))))) -> 0.46131458 | I34: =CEILING(G34/(1-H34)/费率与参数!$B$2,费率与参数!$B$3)*费率与参数!$B$2 -> 1.5 | J34: =I34/费率与参数!$B$2 -> 150 | K34: =1-G34/I34 -> 0.461976 | L34: =成本与现售价!$J$34 -> 81 | M34: =I34/成本与现售价!$K$34-1 -> 0.85185185
A35: Seedance 2.0 Mini（极速版） | B35: Ark官方 | C35: doubao-seedance-2-0-mini-260615 | D35: 480p | E35: 8 | F35: — | G35: =成本与现售价!$I$35 -> 0.92232 | H35: =MIN(0.95,MAX(费率与参数!$B$6,费率与参数!$B$5-(费率与参数!$B$5-费率与参数!$B$6)*(LN(MAX(G35,0.01))-LN(MIN(成本与现售价!$I$4:$I$172)))/(LN(MAX(成本与现售价!$I$4:$I$172))-LN(MIN(成本与现售价!$I$4:$I$172))))) -> 0.45208438 | I35: =CEILING(G35/(1-H35)/费率与参数!$B$2,费率与参数!$B$3)*费率与参数!$B$2 -> 1.69 | J35: =I35/费率与参数!$B$2 -> 169 | K35: =1-G35/I35 -> 0.45424852 | L35: =成本与现售价!$J$35 -> 93 | M35: =I35/成本与现售价!$K$35-1 -> 0.8172043
A36: Seedance 2.0 Mini（极速版） | B36: Ark官方 | C36: doubao-seedance-2-0-mini-260615 | D36: 480p | E36: 9 | F36: — | G36: =成本与现售价!$I$36 -> 1.037616 | H36: =MIN(0.95,MAX(费率与参数!$B$6,费率与参数!$B$5-(费率与参数!$B$5-费率与参数!$B$6)*(LN(MAX(G36,0.01))-LN(MIN(成本与现售价!$I$4:$I$172)))/(LN(MAX(成本与现售价!$I$4:$I$172))-LN(MIN(成本与现售价!$I$4:$I$172))))) -> 0.44394192 | I36: =CEILING(G36/(1-H36)/费率与参数!$B$2,费率与参数!$B$3)*费率与参数!$B$2 -> 1.87 | J36: =I36/费率与参数!$B$2 -> 187 | K36: =1-G36/I36 -> 0.44512513 | L36: =成本与现售价!$J$36 -> 104 | M36: =I36/成本与现售价!$K$36-1 -> 0.79807692
A37: Seedance 2.0 Mini（极速版） | B37: Ark官方 | C37: doubao-seedance-2-0-mini-260615 | D37: 480p | E37: 10 | F37: — | G37: =成本与现售价!$I$37 -> 1.1529 | H37: =MIN(0.95,MAX(费率与参数!$B$6,费率与参数!$B$5-(费率与参数!$B$5-费率与参数!$B$6)*(LN(MAX(G37,0.01))-LN(MIN(成本与现售价!$I$4:$I$172)))/(LN(MAX(成本与现售价!$I$4:$I$172))-LN(MIN(成本与现售价!$I$4:$I$172))))) -> 0.436659 | I37: =CEILING(G37/(1-H37)/费率与参数!$B$2,费率与参数!$B$3)*费率与参数!$B$2 -> 2.05 | J37: =I37/费率与参数!$B$2 -> 205 | K37: =1-G37/I37 -> 0.43760976 | L37: =成本与现售价!$J$37 -> 116 | M37: =I37/成本与现售价!$K$37-1 -> 0.76724138
A38: Seedance 2.0 Mini（极速版） | B38: Ark官方 | C38: doubao-seedance-2-0-mini-260615 | D38: 480p | E38: 11 | F38: — | G38: =成本与现售价!$I$38 -> 1.268196 | H38: =MIN(0.95,MAX(费率与参数!$B$6,费率与参数!$B$5-(费率与参数!$B$5-费率与参数!$B$6)*(LN(MAX(G38,0.01))-LN(MIN(成本与现售价!$I$4:$I$172)))/(LN(MAX(成本与现售价!$I$4:$I$172))-LN(MIN(成本与现售价!$I$4:$I$172))))) -> 0.4300701 | I38: =CEILING(G38/(1-H38)/费率与参数!$B$2,费率与参数!$B$3)*费率与参数!$B$2 -> 2.23 | J38: =I38/费率与参数!$B$2 -> 223 | K38: =1-G38/I38 -> 0.43130224 | L38: =成本与现售价!$J$38 -> 127 | M38: =I38/成本与现售价!$K$38-1 -> 0.75590551
A39: Seedance 2.0 Mini（极速版） | B39: Ark官方 | C39: doubao-seedance-2-0-mini-260615 | D39: 480p | E39: 12 | F39: — | G39: =成本与现售价!$I$39 -> 1.38348 | H39: =MIN(0.95,MAX(费率与参数!$B$6,费率与参数!$B$5-(费率与参数!$B$5-费率与参数!$B$6)*(LN(MAX(G39,0.01))-LN(MIN(成本与现售价!$I$4:$I$172)))/(LN(MAX(成本与现售价!$I$4:$I$172))-LN(MIN(成本与现售价!$I$4:$I$172))))) -> 0.42405554 | I39: =CEILING(G39/(1-H39)/费率与参数!$B$2,费率与参数!$B$3)*费率与参数!$B$2 -> 2.41 | J39: =I39/费率与参数!$B$2 -> 241 | K39: =1-G39/I39 -> 0.42594191 | L39: =成本与现售价!$J$39 -> 139 | M39: =I39/成本与现售价!$K$39-1 -> 0.73381295
A40: Seedance 2.0 Mini（极速版） | B40: Ark官方 | C40: doubao-seedance-2-0-mini-260615 | D40: 480p | E40: 13 | F40: — | G40: =成本与现售价!$I$40 -> 1.498776 | H40: =MIN(0.95,MAX(费率与参数!$B$6,费率与参数!$B$5-(费率与参数!$B$5-费率与参数!$B$6)*(LN(MAX(G40,0.01))-LN(MIN(成本与现售价!$I$4:$I$172)))/(LN(MAX(成本与现售价!$I$4:$I$172))-LN(MIN(成本与现售价!$I$4:$I$172))))) -> 0.4185221 | I40: =CEILING(G40/(1-H40)/费率与参数!$B$2,费率与参数!$B$3)*费率与参数!$B$2 -> 2.58 | J40: =I40/费率与参数!$B$2 -> 258 | K40: =1-G40/I40 -> 0.41907907 | L40: =成本与现售价!$J$40 -> 150 | M40: =I40/成本与现售价!$K$40-1 -> 0.72
A41: Seedance 2.0 Mini（极速版） | B41: Ark官方 | C41: doubao-seedance-2-0-mini-260615 | D41: 480p | E41: 14 | F41: — | G41: =成本与现售价!$I$41 -> 1.61406 | H41: =MIN(0.95,MAX(费率与参数!$B$6,费率与参数!$B$5-(费率与参数!$B$5-费率与参数!$B$6)*(LN(MAX(G41,0.01))-LN(MIN(成本与现售价!$I$4:$I$172)))/(LN(MAX(成本与现售价!$I$4:$I$172))-LN(MIN(成本与现售价!$I$4:$I$172))))) -> 0.41339947 | I41: =CEILING(G41/(1-H41)/费率与参数!$B$2,费率与参数!$B$3)*费率与参数!$B$2 -> 2.76 | J41: =I41/费率与参数!$B$2 -> 276 | K41: =1-G41/I41 -> 0.41519565 | L41: =成本与现售价!$J$41 -> 162 | M41: =I41/成本与现售价!$K$41-1 -> 0.7037037
...

Sheet 利润率曲线
A1: 利润率曲线（X=单条成本元，Y=建议毛利率；每条线是一个“路由×分辨率”，随成本升高从 80% 平滑降到 40%）
A3: 系列 | B3: 成本(元) | C3: 毛利率
A4: Wan3.0 480p | B4: =建议售价清单!G113 -> 1.5 | C4: =建议售价清单!K113 -> 0.41860465
A5: Wan3.0 480p | B5: =建议售价清单!G114 -> 3 | C5: =建议售价清单!K114 -> 0.37106918
A6: Wan3.0 480p | B6: =建议售价清单!G115 -> 4.5 | C6: =建议售价清单!K115 -> 0.34306569
A7: Wan3.0 480p | B7: =建议售价清单!G116 -> 6 | C7: =建议售价清单!K116 -> 0.3227991
A8: Wan3.0 480p | B8: =建议售价清单!G117 -> 9 | C8: =建议售价清单!K117 -> 0.29467085
A9: Wan3.0 480p 编辑延长 | B9: =建议售价清单!G143 -> 3 | C9: =建议售价清单!K143 -> 0.37106918
A10: Wan3.0 480p 编辑延长 | B10: =建议售价清单!G145 -> 4.5 | C10: =建议售价清单!K145 -> 0.34306569
A11: Wan3.0 480p 编辑延长 | B11: =建议售价清单!G147 -> 6 | C11: =建议售价清单!K147 -> 0.3227991
A12: Wan3.0 480p 编辑延长 | B12: =建议售价清单!G149 -> 7.5 | C12: =建议售价清单!K149 -> 0.30747922
A13: Wan3.0 480p 编辑延长 | B13: =建议售价清单!G151 -> 10.5 | C13: =建议售价清单!K151 -> 0.28425358
A14: Wan3.0 720p | B14: =建议售价清单!G118 -> 3 | C14: =建议售价清单!K118 -> 0.37106918
A15: Wan3.0 720p | B15: =建议售价清单!G119 -> 6 | C15: =建议售价清单!K119 -> 0.3227991
A16: Wan3.0 720p | B16: =建议售价清单!G120 -> 9 | C16: =建议售价清单!K120 -> 0.29467085
A17: Wan3.0 720p | B17: =建议售价清单!G121 -> 12 | C17: =建议售价清单!K121 -> 0.27492447
A18: Wan3.0 720p | B18: =建议售价清单!G122 -> 18 | C18: =建议售价清单!K122 -> 0.24686192
A19: Wan3.0 720p 编辑延长 | B19: =建议售价清单!G153 -> 6 | C19: =建议售价清单!K153 -> 0.3227991
A20: Wan3.0 720p 编辑延长 | B20: =建议售价清单!G155 -> 9 | C20: =建议售价清单!K155 -> 0.29467085
A21: Wan3.0 720p 编辑延长 | B21: =建议售价清单!G157 -> 12 | C21: =建议售价清单!K157 -> 0.27492447
A22: Wan3.0 720p 编辑延长 | B22: =建议售价清单!G159 -> 15 | C22: =建议售价清单!K159 -> 0.25962488
A23: Wan3.0 720p 编辑延长 | B23: =建议售价清单!G161 -> 21 | C23: =建议售价清单!K161 -> 0.23608585
A24: Wan3.0 1080p | B24: =建议售价清单!G123 -> 6 | C24: =建议售价清单!K123 -> 0.3227991
A25: Wan3.0 1080p | B25: =建议售价清单!G124 -> 12 | C25: =建议售价清单!K124 -> 0.27492447
A26: Wan3.0 1080p | B26: =建议售价清单!G125 -> 18 | C26: =建议售价清单!K125 -> 0.24686192
A27: Wan3.0 1080p | B27: =建议售价清单!G126 -> 24 | C27: =建议售价清单!K126 -> 0.22680412
A28: Wan3.0 1080p | B28: =建议售价清单!G127 -> 36 | C28: =建议售价清单!K127 -> 0.19893191
A29: Wan3.0 1080p 编辑延长 | B29: =建议售价清单!G163 -> 12 | C29: =建议售价清单!K163 -> 0.27492447
A30: Wan3.0 1080p 编辑延长 | B30: =建议售价清单!G165 -> 18 | C30: =建议售价清单!K165 -> 0.24686192
A31: Wan3.0 1080p 编辑延长 | B31: =建议售价清单!G167 -> 24 | C31: =建议售价清单!K167 -> 0.22680412
A32: Wan3.0 1080p 编辑延长 | B32: =建议售价清单!G169 -> 30 | C32: =建议售价清单!K169 -> 0.21156373
A33: Wan3.0 1080p 编辑延长 | B33: =建议售价清单!G171 -> 42 | C33: =建议售价清单!K171 -> 0.18824894
A34: H3 768p | B34: =建议售价清单!G67 -> 2 | C34: =建议售价清单!K67 -> 0.3993994
A35: H3 768p | B35: =建议售价清单!G68 -> 2.5 | C35: =建议售价清单!K68 -> 0.38423645
A36: H3 768p | B36: =建议售价清单!G69 -> 3 | C36: =建议售价清单!K69 -> 0.37106918
A37: H3 768p | B37: =建议售价清单!G70 -> 3.5 | C37: =建议售价清单!K70 -> 0.36014625
A38: H3 768p | B38: =建议售价清单!G71 -> 4 | C38: =建议售价清单!K71 -> 0.35170178
A39: H3 768p | B39: =建议售价清单!G72 -> 4.5 | C39: =建议售价清单!K72 -> 0.34306569
A40: H3 768p | B40: =建议售价清单!G73 -> 5 | C40: =建议售价清单!K73 -> 0.33598938
A41: H3 768p | B41: =建议售价清单!G74 -> 5.5 | C41: =建议售价清单!K74 -> 0.32926829
...
